<?xml version="1.0" encoding="utf-8"?>
<!-- =================================================================================== -->
<!-- |    This document was autogenerated by xacro from drawer_one_sided_handle.xacro  | -->
<!-- |    EDITING THIS FILE BY HAND IS NOT RECOMMENDED                                 | -->
<!-- =================================================================================== -->
<robot name="drawer">
  <material name="omni/Blue">
    <color rgba="0 0 0.8 1"/>
  </material>
  <material name="omni/Red">
    <color rgba="1 0 0 1"/>
  </material>
  <material name="omni/White">
    <color rgba="1 1 1 1"/>
  </material>
  <material name="omni/Green">
    <color rgba="0 1 0 1"/>
  </material>
  <material name="omni/Yellow">
    <color rgba="1 1 0 1"/>
  </material>
  <material name="omni/LightGrey">
    <color rgba="0.6 0.6 0.6 1"/>
  </material>
  <material name="omni/DarkGrey">
    <color rgba="0.4 0.4 0.4 1"/>
  </material>
  <material name="brown">
    <color rgba="0.87 0.81 0.76 1.0"/>
  </material>
  <!-- RVIZ Configuration -->
  <link name="base_link"/>
  <joint name="base_link__drawer" type="prismatic">
    <origin rpy="0 0 0" xyz="0 0 0"/>
    <parent link="base_link"/>
    <child link="drawer"/>
    <dynamics damping="1.0" friction="1.0"/>
    <limit effort="0.1" lower="0.0" upper="0.5" velocity="10.0"/>
    <axis xyz="1 0 0"/>
  </joint>
  <link name="drawer">
    <visual>
      <origin rpy="0 0 0" xyz="0 0 0"/>
      <geometry>
        <box size="0.5 0.5 0.3"/>
      </geometry>
      <material name="brown"/>
    </visual>
    <collision>
      <origin rpy="0 0 0" xyz="0 0 0"/>
      <geometry>
        <box size="0.5 0.5 0.3"/>
      </geometry>
      <contact_coefficients mu="0.0"/>
    </collision>
    <inertial>
      <!-- CENTER OF MASS -->
      <origin rpy="0 0 0" xyz="0 0 0"/>
      <mass value="0.1"/>
      <!-- box inertia: 1/12*m(y^2+z^2), ... -->
      <inertia ixx="0.017" ixy="0" ixz="0" iyy="0.017" iyz="0" izz="0.025"/>
    </inertial>
  </link>
  <gazebo reference="drawer">
    <material>Gazebo/Wood</material>
  </gazebo>
  <joint name="base_link__left_wall" type="fixed">
    <origin rpy="0 0 0" xyz="-0.005 -0.265 0"/>
    <parent link="base_link"/>
    <child link="left_wall"/>
  </joint>
  <link name="left_wall">
    <visual>
      <origin rpy="0 0 0" xyz="0 0 0"/>
      <geometry>
        <box size="0.505 0.02 0.31"/>
      </geometry>
      <material name="brown"/>
    </visual>
    <collision>
      <origin rpy="0 0 0" xyz="0 0 0.0"/>
      <geometry>
        <box size="0.505 0.02 0.31"/>
      </geometry>
    </collision>
    <inertial>
      <!-- CENTER OF MASS -->
      <origin rpy="0 0 0" xyz="0 0 0"/>
      <mass value="0.05"/>
      <!-- box inertia: 1/12*m(y^2+z^2), ... -->
      <inertia ixx="0.0024125" ixy="0" ixz="0" iyy="0.008778125" iyz="0" izz="0.006385625"/>
    </inertial>
  </link>
  <joint name="base_link__right_wall" type="fixed">
    <origin rpy="0 0 0" xyz="-0.005 0.265 0"/>
    <parent link="base_link"/>
    <child link="right_wall"/>
  </joint>
  <link name="right_wall">
    <visual>
      <origin rpy="0 0 0" xyz="0 0 0"/>
      <geometry>
        <box size="0.505 0.02 0.31"/>
      </geometry>
      <material name="brown"/>
    </visual>
    <collision>
      <origin rpy="0 0 0" xyz="0 0 0.0"/>
      <geometry>
        <box size="0.505 0.02 0.31"/>
      </geometry>
    </collision>
    <inertial>
      <!-- CENTER OF MASS -->
      <origin rpy="0 0 0" xyz="0 0 0"/>
      <mass value="0.05"/>
      <!-- box inertia: 1/12*m(y^2+z^2), ... -->
      <inertia ixx="0.0024125" ixy="0" ixz="0" iyy="0.008778125" iyz="0" izz="0.006385625"/>
    </inertial>
  </link>
  <joint name="base_link__bottom_wall" type="fixed">
    <origin rpy="0 0 0" xyz="-0.005 0 -0.165"/>
    <parent link="base_link"/>
    <child link="bottom_wall"/>
  </joint>
  <link name="bottom_wall">
    <visual>
      <origin rpy="0 0 0" xyz="0 0 0"/>
      <geometry>
        <box size="0.505 0.55 0.02"/>
      </geometry>
      <material name="brown"/>
    </visual>
    <collision>
      <origin rpy="0 0 0" xyz="0 0 0.0"/>
      <geometry>
        <box size="0.505 0.55 0.02"/>
      </geometry>
    </collision>
    <inertial>
      <!-- CENTER OF MASS -->
      <origin rpy="0 0 0" xyz="0 0 0"/>
      <mass value="0.05"/>
      <!-- box inertia: 1/12*m(y^2+z^2), ... -->
      <inertia ixx="0.0075725" ixy="0" ixz="0" iyy="0.006385625" iyz="0" izz="0.013938125"/>
    </inertial>
  </link>
  <joint name="base_link__top_wall" type="fixed">
    <origin rpy="0 0 0" xyz="-0.005 0 0.165"/>
    <parent link="base_link"/>
    <child link="top_wall"/>
  </joint>
  <link name="top_wall">
    <visual>
      <origin rpy="0 0 0" xyz="0 0 0"/>
      <geometry>
        <box size="0.505 0.55 0.02"/>
      </geometry>
      <material name="brown"/>
    </visual>
    <collision>
      <origin rpy="0 0 0" xyz="0 0 0.0"/>
      <geometry>
        <box size="0.505 0.55 0.02"/>
      </geometry>
    </collision>
    <inertial>
      <!-- CENTER OF MASS -->
      <origin rpy="0 0 0" xyz="0 0 0"/>
      <mass value="0.05"/>
      <!-- box inertia: 1/12*m(y^2+z^2), ... -->
      <inertia ixx="0.0075725" ixy="0" ixz="0" iyy="0.006385625" iyz="0" izz="0.013938125"/>
    </inertial>
  </link>
  <joint name="base_link__back_wall" type="fixed">
    <origin rpy="0 0 0" xyz="-0.265 0 0"/>
    <parent link="base_link"/>
    <child link="back_wall"/>
  </joint>
  <link name="back_wall">
    <visual>
      <origin rpy="0 0 0" xyz="0 0 0"/>
      <geometry>
        <box size="0.02 0.55 0.35"/>
      </geometry>
      <material name="brown"/>
    </visual>
    <collision>
      <origin rpy="0 0 0" xyz="0 0 0.0"/>
      <geometry>
        <box size="0.02 0.55 0.35"/>
      </geometry>
    </collision>
    <inertial>
      <!-- CENTER OF MASS -->
      <origin rpy="0 0 0" xyz="0 0 0"/>
      <mass value="0.05"/>
      <!-- box inertia: 1/12*m(y^2+z^2), ... -->
      <inertia ixx="0.010625" ixy="0" ixz="0" iyy="0.0030725" iyz="0" izz="0.015125"/>
    </inertial>
  </link>
  <joint name="drawer__handle_left" type="fixed">
    <origin rpy="0 0 0" xyz="0.3 -0.0725 0"/>
    <parent link="drawer"/>
    <child link="handle_left"/>
  </joint>
  <link name="handle_left">
    <visual>
      <origin rpy="0 0 0" xyz="0 0 0"/>
      <geometry>
        <box size="0.1 0.02 0.02"/>
      </geometry>
      <material name="omni/White"/>
    </visual>
    <collision>
      <origin rpy="0 0 0" xyz="0 0 0.0"/>
      <geometry>
        <box size="0.1 0.02 0.02"/>
      </geometry>
    </collision>
    <inertial>
      <!-- CENTER OF MASS -->
      <origin rpy="0 0 0" xyz="0 0 0"/>
      <mass value="0.05"/>
      <!-- box inertia: 1/12*m(y^2+z^2), ... -->
      <inertia ixx="2e-05" ixy="0" ixz="0" iyy="0.00026" iyz="0" izz="0.00026"/>
    </inertial>
  </link>
  <joint name="drawer__handle_right" type="fixed">
    <origin rpy="0 0 0" xyz="0.3 0.0725 0"/>
    <parent link="drawer"/>
    <child link="handle_right"/>
  </joint>
  <link name="handle_right">
    <visual>
      <origin rpy="0 0 0" xyz="0 0 0"/>
      <geometry>
        <box size="0.1 0.02 0.02"/>
      </geometry>
      <material name="omni/White"/>
    </visual>
    <collision>
      <origin rpy="0 0 0" xyz="0 0 0.0"/>
      <geometry>
        <box size="0.1 0.02 0.02"/>
      </geometry>
    </collision>
    <inertial>
      <!-- CENTER OF MASS -->
      <origin rpy="0 0 0" xyz="0 0 0"/>
      <mass value="0.05"/>
      <!-- box inertia: 1/12*m(y^2+z^2), ... -->
      <inertia ixx="2e-05" ixy="0" ixz="0" iyy="0.00026" iyz="0" izz="0.00026"/>
    </inertial>
  </link>
  <joint name="drawer__handle_grip" type="fixed">
    <origin rpy="0 0 0" xyz="0.36 0 0"/>
    <parent link="drawer"/>
    <child link="handle_grip"/>
  </joint>
  <link name="handle_grip">
    <visual>
      <origin rpy="0 0 0" xyz="0 0 0"/>
      <geometry>
        <box size="0.02 0.165 0.02"/>
      </geometry>
      <material name="omni/White"/>
    </visual>
    <collision>
      <origin rpy="0 0 0" xyz="0 0 0.0"/>
      <geometry>
        <box size="0.02 0.165 0.02"/>
      </geometry>
    </collision>
    <inertial>
      <!-- CENTER OF MASS -->
      <origin rpy="0 0 0" xyz="0 0 0"/>
      <mass value="0.05"/>
      <!-- box inertia: 1/12*m(y^2+z^2), ... -->
      <inertia ixx="0.000690625" ixy="0" ixz="0" iyy="2e-05" iyz="0" izz="0.000690625"/>
    </inertial>
  </link>
</robot>

